Workbook

Sheet Místnosti
A1: Pořadí místností kapitoly 1
A2: Přehled se počítá automaticky z listu Položky — nic tu needituj.
A4: # | B4: Místnost | C4: Fáze | D4: Cena za 4 Normal položky (Kredity) | E4: Boss položka | F4: Podíl na normální ceně kapitoly 1
A5: 1 | B5: Plášť | C5: Survival | D5: =SUMIF(Položky!$C$5:$C$64,B5,Položky!$F$5:$F$64) -> 32 | E5: Tepelný štít | F5: =D5/Ekonomika!$B$14 -> 0.058181818
A6: 2 | B6: Ubikace | C6: Survival | D6: =SUMIF(Položky!$C$5:$C$64,B6,Položky!$F$5:$F$64) -> 28 | E6: Podlaha/výstelka | F6: =D6/Ekonomika!$B$14 -> 0.050909091
A7: 3 | B7: Koupelny | C7: Survival | D7: =SUMIF(Položky!$C$5:$C$64,B7,Položky!$F$5:$F$64) -> 30 | E7: Odvětrávání | F7: =D7/Ekonomika!$B$14 -> 0.054545455
A8: 4 | B8: Jídelna a kuchyň | C8: Survival | D8: =SUMIF(Položky!$C$5:$C$64,B8,Položky!$F$5:$F$64) -> 32 | E8: Zásobník vody | F8: =D8/Ekonomika!$B$14 -> 0.058181818
A9: 5 | B9: Ošetřovna | C9: Survival | D9: =SUMIF(Položky!$C$5:$C$64,B9,Položky!$F$5:$F$64) -> 32 | E9: Osvětlení/sterilizace | F9: =D9/Ekonomika!$B$14 -> 0.058181818
A10: 6 | B10: Kokpit | C10: Funkčnost | D10: =SUMIF(Položky!$C$5:$C$64,B10,Položky!$F$5:$F$64) -> 50 | E10: Okno kokpitu | F10: =D10/Ekonomika!$B$14 -> 0.090909091
A11: 7 | B11: Navigace | C11: Funkčnost | D11: =SUMIF(Položky!$C$5:$C$64,B11,Položky!$F$5:$F$64) -> 48 | E11: Gyroskop | F11: =D11/Ekonomika!$B$14 -> 0.087272727
A12: 8 | B12: Nákladový prostor | C12: Funkčnost | D12: =SUMIF(Položky!$C$5:$C$64,B12,Položky!$F$5:$F$64) -> 42 | E12: Bezpečnostní sítě | F12: =D12/Ekonomika!$B$14 -> 0.076363636
A13: 9 | B13: Strojovna | C13: Funkčnost | D13: =SUMIF(Položky!$C$5:$C$64,B13,Položky!$F$5:$F$64) -> 54 | E13: Filtrace/výfuk | F13: =D13/Ekonomika!$B$14 -> 0.098181818
A14: 10 | B14: Sklad paliva | C14: Funkčnost | D14: =SUMIF(Položky!$C$5:$C$64,B14,Položky!$F$5:$F$64) -> 46 | E14: Izolace nádrží | F14: =D14/Ekonomika!$B$14 -> 0.083636364
A15: 11 | B15: Serverovna / jádro AI | C15: Vrchol | D15: =SUMIF(Položky!$C$5:$C$64,B15,Položky!$F$5:$F$64) -> 76 | E15: Bezpečnostní protokoly | F15: =D15/Ekonomika!$B$14 -> 0.13818182
A16: 12 | B16: Komunikace | C16: Vrchol | D16: =SUMIF(Položky!$C$5:$C$64,B16,Položky!$F$5:$F$64) -> 80 | E16: Nouzový maják | F16: =D16/Ekonomika!$B$14 -> 0.14545455
B17: CELKEM | D17: =SUM(D5:D16) -> 550 | F17: =SUM(F5:F16) -> 1
A19: Každá místnost = 4 kupované položky + 1 povinný boss level (oranžově). Boss se nedá obejít grindem — je to podmínka dokončení místnosti.

Sheet Položky
A1: Položky k opravě — 12 místností × 5 (4 Normal + 1 Boss)
A2: Žluté buňky (Cena u Normal položek) = uprav podle potřeby. Boss položky (oranžové) nemají cenu — musí se vyhrát, ne koupit.
A4: Pořadí | B4: Fáze | C4: Místnost | D4: Položka | E4: Typ | F4: Cena — levná varianta (Kredity) | G4: Cena — drahá varianta (Kredity) | H4: Orientační počet levelů / pokusů
A5: 1 | B5: Survival | C5: Plášť | D5: Trhliny v obšívce | E5: Normal | F5: 8 | G5: =F5*Ekonomika!$B$11 -> 12.8 | H5: =F5/Ekonomika!$B$5 -> 0.53333333
A6: 1 | B6: Survival | C6: Plášť | D6: Prasklá okna | E6: Normal | F6: 8 | G6: =F6*Ekonomika!$B$11 -> 12.8 | H6: =F6/Ekonomika!$B$5 -> 0.53333333
A7: 1 | B7: Survival | C7: Plášť | D7: Poškozené dveře | E7: Normal | F7: 6 | G7: =F7*Ekonomika!$B$11 -> 9.6 | H7: =F7/Ekonomika!$B$5 -> 0.4
A8: 1 | B8: Survival | C8: Plášť | D8: Přetlaková komora | E8: Normal | F8: 10 | G8: =F8*Ekonomika!$B$11 -> 16 | H8: =F8/Ekonomika!$B$5 -> 0.66666667
A9: 1 | B9: Survival | C9: Plášť | D9: Tepelný štít [BOSS] | E9: Boss | F9: 0 | G9: 0 | H9: =1/Ekonomika!$B$8 -> 2.8571429
A10: 2 | B10: Survival | C10: Ubikace | D10: Palandy/lůžka | E10: Normal | F10: 6 | G10: =F10*Ekonomika!$B$11 -> 9.6 | H10: =F10/Ekonomika!$B$5 -> 0.4
A11: 2 | B11: Survival | C11: Ubikace | D11: Osvětlení | E11: Normal | F11: 6 | G11: =F11*Ekonomika!$B$11 -> 9.6 | H11: =F11/Ekonomika!$B$5 -> 0.4
A12: 2 | B12: Survival | C12: Ubikace | D12: Skříňky | E12: Normal | F12: 6 | G12: =F12*Ekonomika!$B$11 -> 9.6 | H12: =F12/Ekonomika!$B$5 -> 0.4
A13: 2 | B13: Survival | C13: Ubikace | D13: Klimatizace | E13: Normal | F13: 10 | G13: =F13*Ekonomika!$B$11 -> 16 | H13: =F13/Ekonomika!$B$5 -> 0.66666667
A14: 2 | B14: Survival | C14: Ubikace | D14: Podlaha/výstelka [BOSS] | E14: Boss | F14: 0 | G14: 0 | H14: =1/Ekonomika!$B$8 -> 2.8571429
A15: 3 | B15: Survival | C15: Koupelny | D15: Sprchový systém | E15: Normal | F15: 8 | G15: =F15*Ekonomika!$B$11 -> 12.8 | H15: =F15/Ekonomika!$B$5 -> 0.53333333
A16: 3 | B16: Survival | C16: Koupelny | D16: Recyklace vody | E16: Normal | F16: 10 | G16: =F16*Ekonomika!$B$11 -> 16 | H16: =F16/Ekonomika!$B$5 -> 0.66666667
A17: 3 | B17: Survival | C17: Koupelny | D17: Toalety | E17: Normal | F17: 6 | G17: =F17*Ekonomika!$B$11 -> 9.6 | H17: =F17/Ekonomika!$B$5 -> 0.4
A18: 3 | B18: Survival | C18: Koupelny | D18: Zrcadla/umyvadla | E18: Normal | F18: 6 | G18: =F18*Ekonomika!$B$11 -> 9.6 | H18: =F18/Ekonomika!$B$5 -> 0.4
A19: 3 | B19: Survival | C19: Koupelny | D19: Odvětrávání [BOSS] | E19: Boss | F19: 0 | G19: 0 | H19: =1/Ekonomika!$B$8 -> 2.8571429
A20: 4 | B20: Survival | C20: Jídelna a kuchyň | D20: Potravinový syntetizér | E20: Normal | F20: 10 | G20: =F20*Ekonomika!$B$11 -> 16 | H20: =F20/Ekonomika!$B$5 -> 0.66666667
A21: 4 | B21: Survival | C21: Jídelna a kuchyň | D21: Stoly a židle | E21: Normal | F21: 6 | G21: =F21*Ekonomika!$B$11 -> 9.6 | H21: =F21/Ekonomika!$B$5 -> 0.4
A22: 4 | B22: Survival | C22: Jídelna a kuchyň | D22: Chladicí box | E22: Normal | F22: 8 | G22: =F22*Ekonomika!$B$11 -> 12.8 | H22: =F22/Ekonomika!$B$5 -> 0.53333333
A23: 4 | B23: Survival | C23: Jídelna a kuchyň | D23: Ohřívač/sporák | E23: Normal | F23: 8 | G23: =F23*Ekonomika!$B$11 -> 12.8 | H23: =F23/Ekonomika!$B$5 -> 0.53333333
A24: 4 | B24: Survival | C24: Jídelna a kuchyň | D24: Zásobník vody [BOSS] | E24: Boss | F24: 0 | G24: 0 | H24: =1/Ekonomika!$B$8 -> 2.8571429
A25: 5 | B25: Survival | C25: Ošetřovna | D25: Lékárnička/medi-stanice | E25: Normal | F25: 8 | G25: =F25*Ekonomika!$B$11 -> 12.8 | H25: =F25/Ekonomika!$B$5 -> 0.53333333
A26: 5 | B26: Survival | C26: Ošetřovna | D26: Skenovací lůžko | E26: Normal | F26: 10 | G26: =F26*Ekonomika!$B$11 -> 16 | H26: =F26/Ekonomika!$B$5 -> 0.66666667
A27: 5 | B27: Survival | C27: Ošetřovna | D27: Zásoby léků | E27: Normal | F27: 6 | G27: =F27*Ekonomika!$B$11 -> 9.6 | H27: =F27/Ekonomika!$B$5 -> 0.4
A28: 5 | B28: Survival | C28: Ošetřovna | D28: Karanténní kapsle | E28: Normal | F28: 8 | G28: =F28*Ekonomika!$B$11 -> 12.8 | H28: =F28/Ekonomika!$B$5 -> 0.53333333
A29: 5 | B29: Survival | C29: Ošetřovna | D29: Osvětlení/sterilizace [BOSS] | E29: Boss | F29: 0 | G29: 0 | H29: =1/Ekonomika!$B$8 -> 2.8571429
A30: 6 | B30: Funkčnost | C30: Kokpit | D30: Přístrojová deska | E30: Normal | F30: 14 | G30: =F30*Ekonomika!$B$11 -> 22.4 | H30: =F30/Ekonomika!$B$5 -> 0.93333333
A31: 6 | B31: Funkčnost | C31: Kokpit | D31: Pilotní sedačky | E31: Normal | F31: 10 | G31: =F31*Ekonomika!$B$11 -> 16 | H31: =F31/Ekonomika!$B$5 -> 0.66666667
A32: 6 | B32: Funkčnost | C32: Kokpit | D32: Hlavní obrazovka/HUD | E32: Normal | F32: 14 | G32: =F32*Ekonomika!$B$11 -> 22.4 | H32: =F32/Ekonomika!$B$5 -> 0.93333333
A33: 6 | B33: Funkčnost | C33: Kokpit | D33: Ovládací páky | E33: Normal | F33: 12 | G33: =F33*Ekonomika!$B$11 -> 19.2 | H33: =F33/Ekonomika!$B$5 -> 0.8
A34: 6 | B34: Funkčnost | C34: Kokpit | D34: Okno kokpitu [BOSS] | E34: Boss | F34: 0 | G34: 0 | H34: =1/Ekonomika!$B$8 -> 2.8571429
A35: 7 | B35: Funkčnost | C35: Navigace | D35: Senzory | E35: Normal | F35: 12 | G35: =F35*Ekonomika!$B$11 -> 19.2 | H35: =F35/Ekonomika!$B$5 -> 0.8
A36: 7 | B36: Funkčnost | C36: Navigace | D36: Radar | E36: Normal | F36: 12 | G36: =F36*Ekonomika!$B$11 -> 19.2 | H36: =F36/Ekonomika!$B$5 -> 0.8
A37: 7 | B37: Funkčnost | C37: Navigace | D37: Palubní počítač | E37: Normal | F37: 14 | G37: =F37*Ekonomika!$B$11 -> 22.4 | H37: =F37/Ekonomika!$B$5 -> 0.93333333
A38: 7 | B38: Funkčnost | C38: Navigace | D38: Hvězdná mapa | E38: Normal | F38: 10 | G38: =F38*Ekonomika!$B$11 -> 16 | H38: =F38/Ekonomika!$B$5 -> 0.66666667
A39: 7 | B39: Funkčnost | C39: Navigace | D39: Gyroskop [BOSS] | E39: Boss | F39: 0 | G39: 0 | H39: =1/Ekonomika!$B$8 -> 2.8571429
A40: 8 | B40: Funkčnost | C40: Nákladový prostor | D40: Regály | E40: Normal | F40: 10 | G40: =F40*Ekonomika!$B$11 -> 16 | H40: =F40/Ekonomika!$B$5 -> 0.66666667
A41: 8 | B41: Funkčnost | C41: Nákladový prostor | D41: Nakládací rampa | E41: Normal | F41: 12 | G41: =F41*Ekonomika!$B$11 -> 19.2 | H41: =F41/Ekonomika!$B$5 -> 0.8
...

Sheet Ekonomika
A1: Tempo a cílové ladění
A2: Uprav modré/žluté buňky (B sloupec) — vpravo se přepočítá dopad na tempo hry.
A4: Vstupní předpoklady
A5: Průměr Kreditů za vyhraný normální level | B5: 15 | C5: vážený průměr přes 1★/2★/3★ odměnu (viz GDD 5.3)
A6: Úspěšnost normálního levelu (win rate) | B6: 0.6 | C6: volná fáze — sníženo z 70 % na 60 %, aby se víc spotřebovávala energie
A7: Průměr pokusů o level / den | B7: 8 | C7: energie: 5 životů, ~30 min/život, + občasná reklama/Stars (viz GDD 5.2)
A8: Úspěšnost BOSS levelu (win rate) | B8: 0.35 | C8: výrazně nižší než normální levely — povinná výzva na konci místnosti
A9: Bonus násobič odměny za výhru boss levelu | B9: 2 | C9: informativní odměna navíc (viz řádek 15) — NEODEČÍTÁ se z ceny, je to bonus/pocket money
A11: Násobič drahé varianty (u Normal položek) | B11: 1.6 | C11: drahá varianta = levná × tenhle násobič (list Položky, sloupec G)
A13: Odvozené hodnoty
A14: Cena Normal položek celkem (Kredity) | B14: =SUMIF(Položky!$E$5:$E$64,"Normal",Položky!$F$5:$F$64) -> 550
A15: Bonus Kreditů za všechny boss výhry (informativní) | B15: =B5*B9*B16 -> 360
A16: Počet boss položek | B16: =COUNTIF(Položky!$E$5:$E$64,"Boss") -> 12
A18: Vyhraných normálních levelů potřeba | B18: =B14/B5 -> 36.666667
A19: Pokusů na normální levely potřeba | B19: =B18/B6 -> 61.111111
A20: Pokusů na boss levely potřeba (očekávaně) | B20: =B16/B8 -> 34.285714
A21: Celkem pokusů potřeba | B21: =B19+B20 -> 95.396825
A22: Dní na kompletní opravu | B22: =B21/B7 -> 11.924603
A23: Týdnů na kompletní opravu | B23: =B22/7 -> 1.7035147
A25: Cílové tempo
A26: Cíl — min. týdnů | B26: 1 | C26: rozhodnutí z GDD (sekce 7): ~1–2 týdny pro běžného neplaceného hráče
A27: Cíl — max. týdnů | B27: 2
A29: Vyhodnocení | B29: =IF(AND(B23>=B26,B23<=B27),"V CÍLI","MIMO CÍL — uprav ceny/úspěšnosti výše") -> V CÍLI
A31: TODO — Mince (booster měna)
A32: Ceny boosterů a jejich zdroj ještě nejsou navržené. Bonus Kreditů z boss levelů (řádek 15) je kandidát na částečné financování boosterů/Mincí místo přímého odečtu z ceny kapitoly 1 — k rozhodnutí později.
